When raising a new exception while another exception is already being handled, the new exceptionâ€™s __context__ attribute is automatically set to the handled exception. An exception may be handled when an except or finally clause, or a with statement, is used.
